<?xml version="1.0" ?>
<!-- =================================================================================== -->
<!-- |    This document was autogenerated by xacro from ./src/gz_models/models/urdf/diff_drive.xacro | -->
<!-- |    EDITING THIS FILE BY HAND IS NOT RECOMMENDED                                 | -->
<!-- =================================================================================== -->
<robot name="diff_drive">
  <link name="base_link"/>
  <!-- Chassis -->
  <link name="chassis">
    <inertial>
      <mass value="1.14395"/>
      <inertia ixx="0.126164" ixy="0" ixz="0" iyy="0.416519" iyz="0" izz="0.481014"/>
    </inertial>
    <visual>
      <origin rpy="0 0 0" xyz="0 0 0"/>
      <geometry>
        <box size="2.01142 1 0.568726"/>
      </geometry>
      <material name="blue">
        <color rgba="0.5 0.5 1.0 1"/>
      </material>
    </visual>
    <collision>
      <origin rpy="0 0 0" xyz="0 0 0"/>
      <geometry>
        <box size="2.01142 1 0.568726"/>
      </geometry>
    </collision>
  </link>
  <joint name="chassis_joint" type="fixed">
    <parent link="base_link"/>
    <child link="chassis"/>
    <origin rpy="0 0 0" xyz="0 0 0"/>
  </joint>
  <link name="left_wheel">
    <inertial>
      <mass value="2"/>
      <inertia ixx="0.145833" ixy="0" ixz="0" iyy="0.145833" iyz="0" izz="0.125"/>
    </inertial>
    <visual>
      <origin rpy="0 0 0" xyz="0 0 0"/>
      <geometry>
        <cylinder length="0.2" radius="0.3"/>
      </geometry>
      <material name="dark_gray">
        <color rgba="0.2 0.2 0.2 1"/>
      </material>
    </visual>
    <collision name="wheel_collision">
      <origin rpy="0 0 0" xyz="0 0 0"/>
      <geometry>
        <cylinder length="0.2" radius="0.3"/>
      </geometry>
    </collision>
  </link>
  <joint name="left_wheel_joint" type="revolute">
    <parent link="chassis"/>
    <child link="left_wheel"/>
    <origin rpy="-1.5707 0 0" xyz="0.554283 0.625029 -0.025"/>
    <axis xyz="0 0 1"/>
    <limit effort="1000.0" lower="-1.79769e+308" upper="1.79769e+308" velocity="50.0"/>
  </joint>
  <!-- <gazebo reference="${name}_wheel">
            <sensor name="contact_sensor" type="contact">
                <always_on>true</always_on>
                <update_rate>30.0</update_rate>
                <topic>${name}_wheel_contacts</topic>
                <contact>
                    <collision>wheel_collision</collision>
                </contact>
            </sensor>
        </gazebo> -->
  <link name="right_wheel">
    <inertial>
      <mass value="2"/>
      <inertia ixx="0.145833" ixy="0" ixz="0" iyy="0.145833" iyz="0" izz="0.125"/>
    </inertial>
    <visual>
      <origin rpy="0 0 0" xyz="0 0 0"/>
      <geometry>
        <cylinder length="0.2" radius="0.3"/>
      </geometry>
      <material name="dark_gray">
        <color rgba="0.2 0.2 0.2 1"/>
      </material>
    </visual>
    <collision name="wheel_collision">
      <origin rpy="0 0 0" xyz="0 0 0"/>
      <geometry>
        <cylinder length="0.2" radius="0.3"/>
      </geometry>
    </collision>
  </link>
  <joint name="right_wheel_joint" type="revolute">
    <parent link="chassis"/>
    <child link="right_wheel"/>
    <origin rpy="-1.5707 0 0" xyz="0.554283 -0.625029 -0.025"/>
    <axis xyz="0 0 1"/>
    <limit effort="1000.0" lower="-1.79769e+308" upper="1.79769e+308" velocity="50.0"/>
  </joint>
  <!-- <gazebo reference="${name}_wheel">
            <sensor name="contact_sensor" type="contact">
                <always_on>true</always_on>
                <update_rate>30.0</update_rate>
                <topic>${name}_wheel_contacts</topic>
                <contact>
                    <collision>wheel_collision</collision>
                </contact>
            </sensor>
        </gazebo> -->
  <!-- Caster -->
  <link name="caster">
    <inertial>
      <mass value="1"/>
      <inertia ixx="0.1" ixy="0" ixz="0" iyy="0.1" iyz="0" izz="0.1"/>
    </inertial>
    <visual>
      <origin rpy="0 0 0" xyz="0 0 0"/>
      <geometry>
        <sphere radius="0.2"/>
      </geometry>
      <material name="dark_gray">
        <color rgba="0.2 0.2 0.2 1"/>
      </material>
    </visual>
    <collision>
      <origin rpy="0 0 0" xyz="0 0 0"/>
      <geometry>
        <sphere radius="0.2"/>
      </geometry>
    </collision>
  </link>
  <joint name="caster_wheel" type="fixed">
    <parent link="chassis"/>
    <child link="caster"/>
    <origin rpy="0 0 0" xyz="-0.957138 0 -0.125"/>
  </joint>
  <!-- Lidar -->
  <link name="lidar_link">
    <inertial>
      <mass value="0.1"/>
      <inertia ixx="0.000166667" ixy="0" ixz="0" iyy="0.000166667" iyz="0" izz="0.000166667"/>
    </inertial>
    <visual>
      <origin rpy="0 0 0" xyz="0 0 0"/>
      <geometry>
        <box size="0.1 0.1 0.1"/>
      </geometry>
    </visual>
    <collision>
      <origin rpy="0 0 0" xyz="0 0 0"/>
      <geometry>
        <box size="0.1 0.1 0.1"/>
      </geometry>
    </collision>
  </link>
  <joint name="lidar_joint" type="fixed">
    <parent link="chassis"/>
    <child link="lidar_link"/>
    <origin rpy="0 0 0" xyz="0 0 0.5"/>
  </joint>
  <!-- Gazebo Plugins -->
  <gazebo>
    <plugin filename="gz-sim8-diff-drive-system" name="gz::sim::systems::DiffDrive">
      <left_joint>left_wheel_joint</left_joint>
      <right_joint>right_wheel_joint</right_joint>
      <wheel_separation>1.25</wheel_separation>
      <wheel_radius>0.3</wheel_radius>
      <odom_publish_frequency>1</odom_publish_frequency>
      <max_linear_acceleration>1</max_linear_acceleration>
      <min_linear_acceleration>-1</min_linear_acceleration>
      <max_angular_acceleration>2</max_angular_acceleration>
      <min_angular_acceleration>-2</min_angular_acceleration>
      <max_linear_velocity>20</max_linear_velocity>
      <min_linear_velocity>-20</min_linear_velocity>
      <max_angular_velocity>1</max_angular_velocity>
      <min_angular_velocity>-1</min_angular_velocity>
    </plugin>
    <plugin filename="gz-sim-joint-state-publisher-system" name="gz::sim::systems::JointStatePublisher">
        </plugin>
    <!-- <plugin
            filename="gz-sim-pose-publisher-system"
            name="gz::sim::systems::PosePublisher">
            <publish_link_pose>true</publish_link_pose>
            <use_pose_vector_msg>true</use_pose_vector_msg>
            <static_publisher>true</static_publisher>
            <static_update_frequency>1</static_update_frequency>
        </plugin> -->
    <plugin filename="gz-sim-odometry-publisher-system" name="gz::sim::systems::OdometryPublisher">
      <odom_frame>diff_drive_robot/odom</odom_frame>
      <robot_base_frame>diff_drive_robot/base_link</robot_base_frame>
      <odom_publish_frequency>20</odom_publish_frequency>
    </plugin>
  </gazebo>
  <!-- Gazebo Sensor for Lidar -->
  <gazebo reference="lidar_link">
    <sensor name="my_lidar" type="gpu_lidar">
      <pose>0 0 0 0 0 0</pose>
      <topic>/model/diff_drive_robot/scan</topic>
      <gz_frame_id>diff_drive_robot/lidar_link</gz_frame_id>
      <update_rate>10</update_rate>
      <lidar>
        <scan>
          <horizontal>
            <samples>640</samples>
            <resolution>1</resolution>
            <min_angle>-1.396263</min_angle>
            <max_angle>1.396263</max_angle>
          </horizontal>
          <vertical>
            <samples>1</samples>
            <resolution>1</resolution>
            <min_angle>0.0</min_angle>
            <max_angle>0.0</max_angle>
          </vertical>
        </scan>
        <range>
          <min>0.08</min>
          <max>10.0</max>
          <resolution>0.01</resolution>
        </range>
      </lidar>
      <always_on>1</always_on>
      <visualize>true</visualize>
    </sensor>
  </gazebo>
</robot>
