<?xml version="1.0"?>
<robot name="diff_drive" xmlns:xacro="http://ros.org/wiki/xacro">

    <!-- Chassis -->
    <link name="chassis">
        <inertial>
            <mass value="1.14395" />
            <inertia ixx="0.126164" ixy="0" ixz="0" iyy="0.416519" iyz="0" izz="0.481014" />
        </inertial>
        <visual>
            <origin xyz="0 0 0" rpy="0 0 0" />
            <geometry>
                <box size="2.01142 1 0.568726" />
            </geometry>
            <material name="blue">
                <color rgba="0.5 0.5 1.0 1" />
            </material>
        </visual>
        <collision>
            <origin xyz="0 0 0" rpy="0 0 0" />
            <geometry>
                <box size="2.01142 1 0.568726" />
            </geometry>
        </collision>
    </link>

    <!-- Left Wheel -->
    <link name="left_wheel">
        <inertial>
            <mass value="2" />
            <inertia ixx="0.145833" ixy="0" ixz="0" iyy="0.145833" iyz="0" izz="0.125" />
        </inertial>
        <visual>
            <origin xyz="0 0 0" rpy="0 0 0" />
            <geometry>
                <cylinder radius="0.3" length="0.2" />
            </geometry>
            <material name="dark_gray">
                <color rgba="0.2 0.2 0.2 1" />
            </material>
        </visual>
        <collision>
            <origin xyz="0 0 0" rpy="0 0 0" />
            <geometry>
                <cylinder radius="0.3" length="0.2" />
            </geometry>
        </collision>
    </link>

    <!-- Right Wheel -->
    <link name="right_wheel">
        <inertial>
            <mass value="2" />
            <inertia ixx="0.145833" ixy="0" ixz="0" iyy="0.145833" iyz="0" izz="0.125" />
        </inertial>
        <visual>
            <origin xyz="0 0 0" rpy="0 0 0" />
            <geometry>
                <cylinder radius="0.3" length="0.2" />
            </geometry>
            <material name="dark_gray">
                <color rgba="0.2 0.2 0.2 1" />
            </material>
        </visual>
        <collision>
            <origin xyz="0 0 0" rpy="0 0 0" />
            <geometry>
                <cylinder radius="0.3" length="0.2" />
            </geometry>
        </collision>
    </link>

    <!-- Caster -->
    <link name="caster">
        <inertial>
            <mass value="1" />
            <inertia ixx="0.1" ixy="0" ixz="0" iyy="0.1" iyz="0" izz="0.1" />
        </inertial>
        <visual>
            <origin xyz="0 0 0" rpy="0 0 0" />
            <geometry>
                <sphere radius="0.2" />
            </geometry>
            <material name="dark_gray">
                <color rgba="0.2 0.2 0.2 1" />
            </material>
        </visual>
        <collision>
            <origin xyz="0 0 0" rpy="0 0 0" />
            <geometry>
                <sphere radius="0.2" />
            </geometry>
        </collision>
    </link>

    <!-- Lidar -->
    <link name="lidar_link">
        <inertial>
            <mass value="0.1" />
            <inertia ixx="0.000166667" ixy="0" ixz="0" iyy="0.000166667" iyz="0" izz="0.000166667" />
        </inertial>
        <visual>
            <origin xyz="0 0 0" rpy="0 0 0" />
            <geometry>
                <box size="0.1 0.1 0.1" />
            </geometry>
        </visual>
        <collision>
            <origin xyz="0 0 0" rpy="0 0 0" />
            <geometry>
                <box size="0.1 0.1 0.1" />
            </geometry>
        </collision>
    </link>

    <!-- Joints -->
    <joint name="lidar_joint" type="fixed">
        <parent link="chassis" />
        <child link="lidar_link" />
        <origin xyz="0 0 0.5" rpy="0 0 0" />
    </joint>

    <joint name="left_wheel_joint" type="revolute">
        <parent link="chassis" />
        <child link="left_wheel" />
        <origin xyz="0.554283 0.625029 -0.025" rpy="-1.5707 0 0" />
        <axis xyz="0 0 1" />
        <limit lower="-1.79769e+308" upper="1.79769e+308" effort="1000.0" velocity="50.0" />
    </joint>

    <joint name="right_wheel_joint" type="revolute">
        <parent link="chassis" />
        <child link="right_wheel" />
        <origin xyz="0.554282 -0.625029 -0.025" rpy="-1.5707 0 0" />
        <axis xyz="0 0 1" />
        <limit lower="-1.79769e+308" upper="1.79769e+308" effort="1000.0" velocity="50.0" />
    </joint>

    <joint name="caster_wheel" type="fixed">
        <parent link="chassis" />
        <child link="caster" />
        <origin xyz="-0.957138 0 -0.125" rpy="0 0 0" />
    </joint>

</robot>